{
 "cells": [
  {
   "cell_type": "code",
   "execution_count": 1,
   "metadata": {},
   "outputs": [],
   "source": [
    "import os"
   ]
  },
  {
   "cell_type": "code",
   "execution_count": 4,
   "metadata": {},
   "outputs": [
    {
     "data": {
      "text/plain": [
       "'/Users/farzanasyeda/Documents/CnnClassifier/Cnn-Classifier'"
      ]
     },
     "execution_count": 4,
     "metadata": {},
     "output_type": "execute_result"
    }
   ],
   "source": [
    "%pwd"
   ]
  },
  {
   "cell_type": "code",
   "execution_count": 3,
   "metadata": {},
   "outputs": [],
   "source": [
    "os.chdir(\"../\")"
   ]
  },
  {
   "cell_type": "code",
   "execution_count": 7,
   "metadata": {},
   "outputs": [],
   "source": [
    "from dataclasses import dataclass\n",
    "from pathlib import Path\n",
    "\n",
    "@dataclass(frozen=True)\n",
    "class PrepareCallbacksConfig:\n",
    "    root_dir: Path\n",
    "    tensorboard_root_log_dir: Path\n",
    "    checkpoint_model_filepath: Path"
   ]
  },
  {
   "cell_type": "markdown",
   "metadata": {},
   "source": []
  },
  {
   "cell_type": "code",
   "execution_count": 8,
   "metadata": {},
   "outputs": [],
   "source": [
    "from cnnclassifier.constants import *\n",
    "from cnnclassifier.utils import read_yaml, create_directories"
   ]
  },
  {
   "cell_type": "code",
   "execution_count": 13,
   "metadata": {},
   "outputs": [],
   "source": [
    "class ConfigurationManager:\n",
    "    def __init__(\n",
    "        self, \n",
    "        config_filepath = CONFIG_FILE_PATH,\n",
    "        params_filepath = PARAMS_FILE_PATH):\n",
    "        self.config = read_yaml(config_filepath)\n",
    "        self.params = read_yaml(params_filepath)\n",
    "        create_directories([self.config.artifacts_root])\n",
    "\n",
    "    def get_prepare_callback_config(self) -> PrepareCallbacksConfig:\n",
    "        config = self.config.prepare_callbacks\n",
    "        model_ckpt_dir = os.path.dirname(config.checkpoint_model_filepath)\n",
    "        create_directories([\n",
    "            Path(model_ckpt_dir),\n",
    "            Path(config.tensorboard_root_log_dir)\n",
    "        ])\n",
    "\n",
    "        prepare_callback_config = PrepareCallbacksConfig(\n",
    "            root_dir=Path(config.root_dir),\n",
    "            tensorboard_root_log_dir=Path(config.tensorboard_root_log_dir),\n",
    "            checkpoint_model_filepath=Path(config.checkpoint_model_filepath)\n",
    "        )\n",
    "\n",
    "        return prepare_callback_config"
   ]
  },
  {
   "cell_type": "code",
   "execution_count": 14,
   "metadata": {},
   "outputs": [
    {
     "name": "stderr",
     "output_type": "stream",
     "text": [
      "2024-04-24 20:29:48.400251: I tensorflow/core/platform/cpu_feature_guard.cc:210] This TensorFlow binary is optimized to use available CPU instructions in performance-critical operations.\n",
      "To enable the following instructions: AVX2 FMA, in other operations, rebuild TensorFlow with the appropriate compiler flags.\n"
     ]
    }
   ],
   "source": [
    "import os\n",
    "import urllib.request as request\n",
    "from zipfile import ZipFile\n",
    "import tensorflow as tf\n",
    "import time"
   ]
  },
  {
   "cell_type": "code",
   "execution_count": 15,
   "metadata": {},
   "outputs": [],
   "source": [
    "class PrepareCallback:\n",
    "    def __init__(self, config: PrepareCallbacksConfig):\n",
    "        self.config = config\n",
    "\n",
    "    \n",
    "    @property\n",
    "    def _create_tb_callbacks(self):\n",
    "        timestamp = time.strftime(\"%Y-%m-%d-%H-%M-%S\")\n",
    "        tb_running_log_dir = os.path.join(\n",
    "            self.config.tensorboard_root_log_dir,\n",
    "            f\"tb_logs_at_{timestamp}\",\n",
    "        )\n",
    "        return tf.keras.callbacks.TensorBoard(log_dir=tb_running_log_dir)\n",
    "    \n",
    "\n",
    "    @property\n",
    "    def _create_ckpt_callbacks(self):\n",
    "        return tf.keras.callbacks.ModelCheckpoint(\n",
    "            filepath=self.config.checkpoint_model_filepath,\n",
    "            save_best_only=True\n",
    "        )\n",
    "\n",
    "\n",
    "    def get_tb_ckpt_callbacks(self):\n",
    "        return [\n",
    "            self._create_tb_callbacks,\n",
    "            self._create_ckpt_callbacks\n",
    "        ]"
   ]
  },
  {
   "cell_type": "code",
   "execution_count": 16,
   "metadata": {},
   "outputs": [
    {
     "name": "stdout",
     "output_type": "stream",
     "text": [
      "[2024-04-24 20:30:46,708: INFO: common: yaml file: config/config.yaml loaded successfully]\n",
      "[2024-04-24 20:30:46,713: INFO: common: yaml file: params.yaml loaded successfully]\n",
      "[2024-04-24 20:30:46,715: INFO: common: created directory at: artifacts]\n"
     ]
    },
    {
     "ename": "BoxKeyError",
     "evalue": "\"'ConfigBox' object has no attribute 'prepare_callbacks'\"",
     "output_type": "error",
     "traceback": [
      "\u001b[0;31m---------------------------------------------------------------------------\u001b[0m",
      "\u001b[0;31mKeyError\u001b[0m                                  Traceback (most recent call last)",
      "File \u001b[0;32m/opt/anaconda3/envs/cnncls/lib/python3.9/site-packages/box/box.py:503\u001b[0m, in \u001b[0;36mbox.box.Box.__getitem__\u001b[0;34m()\u001b[0m\n",
      "\u001b[0;31mKeyError\u001b[0m: 'prepare_callbacks'",
      "\nThe above exception was the direct cause of the following exception:\n",
      "\u001b[0;31mBoxKeyError\u001b[0m                               Traceback (most recent call last)",
      "File \u001b[0;32m/opt/anaconda3/envs/cnncls/lib/python3.9/site-packages/box/box.py:536\u001b[0m, in \u001b[0;36mbox.box.Box.__getattr__\u001b[0;34m()\u001b[0m\n",
      "File \u001b[0;32m/opt/anaconda3/envs/cnncls/lib/python3.9/site-packages/box/box.py:524\u001b[0m, in \u001b[0;36mbox.box.Box.__getitem__\u001b[0;34m()\u001b[0m\n",
      "\u001b[0;31mBoxKeyError\u001b[0m: \"'prepare_callbacks'\"",
      "\nDuring handling of the above exception, another exception occurred:\n",
      "\u001b[0;31mAttributeError\u001b[0m                            Traceback (most recent call last)",
      "File \u001b[0;32m/opt/anaconda3/envs/cnncls/lib/python3.9/site-packages/box/box.py:538\u001b[0m, in \u001b[0;36mbox.box.Box.__getattr__\u001b[0;34m()\u001b[0m\n",
      "\u001b[0;31mAttributeError\u001b[0m: 'ConfigBox' object has no attribute 'prepare_callbacks'",
      "\nThe above exception was the direct cause of the following exception:\n",
      "\u001b[0;31mBoxKeyError\u001b[0m                               Traceback (most recent call last)",
      "File \u001b[0;32m/opt/anaconda3/envs/cnncls/lib/python3.9/site-packages/box/config_box.py:28\u001b[0m, in \u001b[0;36mbox.config_box.ConfigBox.__getattr__\u001b[0;34m()\u001b[0m\n",
      "File \u001b[0;32m/opt/anaconda3/envs/cnncls/lib/python3.9/site-packages/box/box.py:552\u001b[0m, in \u001b[0;36mbox.box.Box.__getattr__\u001b[0;34m()\u001b[0m\n",
      "\u001b[0;31mBoxKeyError\u001b[0m: \"'ConfigBox' object has no attribute 'prepare_callbacks'\"",
      "\nDuring handling of the above exception, another exception occurred:\n",
      "\u001b[0;31mKeyError\u001b[0m                                  Traceback (most recent call last)",
      "File \u001b[0;32m/opt/anaconda3/envs/cnncls/lib/python3.9/site-packages/box/box.py:503\u001b[0m, in \u001b[0;36mbox.box.Box.__getitem__\u001b[0;34m()\u001b[0m\n",
      "\u001b[0;31mKeyError\u001b[0m: 'prepare_callbacks'",
      "\nThe above exception was the direct cause of the following exception:\n",
      "\u001b[0;31mBoxKeyError\u001b[0m                               Traceback (most recent call last)",
      "File \u001b[0;32m/opt/anaconda3/envs/cnncls/lib/python3.9/site-packages/box/box.py:536\u001b[0m, in \u001b[0;36mbox.box.Box.__getattr__\u001b[0;34m()\u001b[0m\n",
      "File \u001b[0;32m/opt/anaconda3/envs/cnncls/lib/python3.9/site-packages/box/box.py:524\u001b[0m, in \u001b[0;36mbox.box.Box.__getitem__\u001b[0;34m()\u001b[0m\n",
      "\u001b[0;31mBoxKeyError\u001b[0m: \"'prepare_callbacks'\"",
      "\nDuring handling of the above exception, another exception occurred:\n",
      "\u001b[0;31mAttributeError\u001b[0m                            Traceback (most recent call last)",
      "File \u001b[0;32m/opt/anaconda3/envs/cnncls/lib/python3.9/site-packages/box/box.py:538\u001b[0m, in \u001b[0;36mbox.box.Box.__getattr__\u001b[0;34m()\u001b[0m\n",
      "\u001b[0;31mAttributeError\u001b[0m: 'ConfigBox' object has no attribute 'prepare_callbacks'",
      "\nThe above exception was the direct cause of the following exception:\n",
      "\u001b[0;31mBoxKeyError\u001b[0m                               Traceback (most recent call last)",
      "Cell \u001b[0;32mIn[16], line 8\u001b[0m\n\u001b[1;32m      5\u001b[0m     callback_list \u001b[38;5;241m=\u001b[39m prepare_callbacks\u001b[38;5;241m.\u001b[39mget_tb_ckpt_callbacks()\n\u001b[1;32m      7\u001b[0m \u001b[38;5;28;01mexcept\u001b[39;00m \u001b[38;5;167;01mException\u001b[39;00m \u001b[38;5;28;01mas\u001b[39;00m e:\n\u001b[0;32m----> 8\u001b[0m     \u001b[38;5;28;01mraise\u001b[39;00m e\n",
      "Cell \u001b[0;32mIn[16], line 3\u001b[0m\n\u001b[1;32m      1\u001b[0m \u001b[38;5;28;01mtry\u001b[39;00m:\n\u001b[1;32m      2\u001b[0m     config \u001b[38;5;241m=\u001b[39m ConfigurationManager()\n\u001b[0;32m----> 3\u001b[0m     prepare_callbacks_config \u001b[38;5;241m=\u001b[39m \u001b[43mconfig\u001b[49m\u001b[38;5;241;43m.\u001b[39;49m\u001b[43mget_prepare_callback_config\u001b[49m\u001b[43m(\u001b[49m\u001b[43m)\u001b[49m\n\u001b[1;32m      4\u001b[0m     prepare_callbacks \u001b[38;5;241m=\u001b[39m PrepareCallback(config\u001b[38;5;241m=\u001b[39mprepare_callbacks_config)\n\u001b[1;32m      5\u001b[0m     callback_list \u001b[38;5;241m=\u001b[39m prepare_callbacks\u001b[38;5;241m.\u001b[39mget_tb_ckpt_callbacks()\n",
      "Cell \u001b[0;32mIn[13], line 11\u001b[0m, in \u001b[0;36mConfigurationManager.get_prepare_callback_config\u001b[0;34m(self)\u001b[0m\n\u001b[1;32m     10\u001b[0m \u001b[38;5;28;01mdef\u001b[39;00m \u001b[38;5;21mget_prepare_callback_config\u001b[39m(\u001b[38;5;28mself\u001b[39m) \u001b[38;5;241m-\u001b[39m\u001b[38;5;241m>\u001b[39m PrepareCallbacksConfig:\n\u001b[0;32m---> 11\u001b[0m     config \u001b[38;5;241m=\u001b[39m \u001b[38;5;28;43mself\u001b[39;49m\u001b[38;5;241;43m.\u001b[39;49m\u001b[43mconfig\u001b[49m\u001b[38;5;241;43m.\u001b[39;49m\u001b[43mprepare_callbacks\u001b[49m\n\u001b[1;32m     12\u001b[0m     model_ckpt_dir \u001b[38;5;241m=\u001b[39m os\u001b[38;5;241m.\u001b[39mpath\u001b[38;5;241m.\u001b[39mdirname(config\u001b[38;5;241m.\u001b[39mcheckpoint_model_filepath)\n\u001b[1;32m     13\u001b[0m     create_directories([\n\u001b[1;32m     14\u001b[0m         Path(model_ckpt_dir),\n\u001b[1;32m     15\u001b[0m         Path(config\u001b[38;5;241m.\u001b[39mtensorboard_root_log_dir)\n\u001b[1;32m     16\u001b[0m     ])\n",
      "File \u001b[0;32m/opt/anaconda3/envs/cnncls/lib/python3.9/site-packages/box/config_box.py:30\u001b[0m, in \u001b[0;36mbox.config_box.ConfigBox.__getattr__\u001b[0;34m()\u001b[0m\n",
      "File \u001b[0;32m/opt/anaconda3/envs/cnncls/lib/python3.9/site-packages/box/box.py:552\u001b[0m, in \u001b[0;36mbox.box.Box.__getattr__\u001b[0;34m()\u001b[0m\n",
      "\u001b[0;31mBoxKeyError\u001b[0m: \"'ConfigBox' object has no attribute 'prepare_callbacks'\""
     ]
    }
   ],
   "source": [
    "try:\n",
    "    config = ConfigurationManager()\n",
    "    prepare_callbacks_config = config.get_prepare_callback_config()\n",
    "    prepare_callbacks = PrepareCallback(config=prepare_callbacks_config)\n",
    "    callback_list = prepare_callbacks.get_tb_ckpt_callbacks()\n",
    "    \n",
    "except Exception as e:\n",
    "    raise e"
   ]
  }
 ],
 "metadata": {
  "kernelspec": {
   "display_name": "cnncls",
   "language": "python",
   "name": "python3"
  },
  "language_info": {
   "codemirror_mode": {
    "name": "ipython",
    "version": 3
   },
   "file_extension": ".py",
   "mimetype": "text/x-python",
   "name": "python",
   "nbconvert_exporter": "python",
   "pygments_lexer": "ipython3",
   "version": "3.9.19"
  }
 },
 "nbformat": 4,
 "nbformat_minor": 2
}
